<?xml version='1.0'?>
<robot name='mobile'>

<link name="base_footprint"/>

  <joint name="base_link_joint" type="fixed">
    <origin xyz="0.0 0 0" rpy="0 0 0" />
    <parent link="base_footprint"/>
    <child link="base_link" />
  </joint>
  
<link name="base_link">
          <visual>
              <origin xyz="0 0 0.1" rpy="0 0 1.57"/>
              <geometry>
              <box size="0.2 .3 .1"/>           
              </geometry>
              <material name="blue">
              <color rgba="0 0 1 1"/>              
              </material>
          </visual>    
      <collision>
        <origin xyz="0 0 0.1" rpy="0 0 1.57"/>
        <geometry>
         <box size="0.2 .3 .1"/>
          </geometry>
</collision>
<inertial>
   <mass
        value="5.52" />
      <inertia
        ixx="0.0458"
        ixy="0"
        ixz="0"
        iyy="0.0229"
        iyz="0"
        izz="0.0595" />
</inertial>
</link>

<link name="wheel_1">
          <visual>
              <origin xyz="0 0 0" rpy="0 0 0"/>
              <geometry>
              <cylinder length="0.04" radius="0.05"/>          
              </geometry>
              <material name="blue">
              <color rgba="0 0 1 1"/>              
              </material>
          </visual>    
      <collision>
        <origin xyz="0 0 0" rpy="0 0 0"/>
        <geometry>
         <cylinder length="0.05" radius="0.05"/>
          </geometry>
</collision>
<inertial>
   <mass
        value="0.2" />
      <inertia
        ixx="0.0002"
        ixy="0"
        ixz="0"
        iyy="0.00015"
        iyz="0"
        izz="0.0002" />
</inertial>
</link>

<joint name="base_to_wheel1" type="continuous">
<parent link="base_link"/>
<child link="wheel_1"/>
<origin xyz="0.125 0.125 0.045" rpy="0 1.57 1.57"/>
<axis xyz="0 0 1"/>
</joint>

<link name="wheel_2">
          <visual>
              <origin xyz="0 0 0" rpy="0 0 0"/>
              <geometry>
              <cylinder length="0.04" radius="0.05"/>          
              </geometry>
              <material name="blue">
              <color rgba="0 0 1 1"/>              
              </material>
          </visual>    
      <collision>
        <origin xyz="0 0 0" rpy="0 0 0"/>
        <geometry>
         <cylinder length="0.05" radius="0.05"/>
          </geometry>
</collision>
<inertial>
  <mass
        value="0.2" />
      <inertia
        ixx="0.0002"
        ixy="0"
        ixz="0"
        iyy="0.00015"
        iyz="0"
        izz="0.0002" />
</inertial>
</link>

<joint name="base_to_wheel2" type="continuous">
<parent link="base_link"/>
<child link="wheel_2"/>
<origin xyz="-0.125 0.125 0.06" rpy="0 1.57 1.57"/>
<axis xyz="0 0 1"/>
</joint>

<link name="wheel_3">
          <visual>
              <origin xyz="0 0 0" rpy="0 0 0"/>
              <geometry>
              <cylinder length="0.04" radius="0.05"/>          
              </geometry>
              <material name="blue">
              <color rgba="0 0 1 1"/>              
              </material>
          </visual>    
      <collision>
        <origin xyz="0 0 0" rpy="0 0 0"/>
        <geometry>
         <cylinder length="0.05" radius="0.05"/>
          </geometry>
</collision>
<inertial>
  <mass
        value="0.2" />
      <inertia
        ixx="0.0002"
        ixy="0"
        ixz="0"
        iyy="0.00015"
        iyz="0"
        izz="0.0002" />
</inertial>
</link>

<joint name="base_to_wheel3" type="continuous">
<parent link="base_link"/>
<child link="wheel_3"/>
<origin xyz="0.125 -0.125 0.06" rpy="0 1.57 1.57"/>
<axis xyz="0 0 1"/>
</joint>

<link name="wheel_4">
          <visual>
              <origin xyz="0 0 0" rpy="0 0 0"/>
              <geometry>
              <cylinder length="0.04" radius="0.05"/>          
              </geometry>
              <material name="blue">
              <color rgba="0 0 1 1"/>              
              </material>
          </visual>    
      <collision>
        <origin xyz="0 0 0" rpy="0 0 0"/>
        <geometry>
         <cylinder length="0.05" radius="0.05"/>
          </geometry>
</collision>
<inertial>
   <mass
        value="0.2" />
      <inertia
        ixx="0.0002"
        ixy="0"
        ixz="0"
        iyy="0.00015"
        iyz="0"
        izz="0.0002" />
</inertial>
</link>


<joint name="base_to_wheel4" type="continuous">
<parent link="base_link"/>
<child link="wheel_4"/>
<origin xyz="-0.125 -0.125 0.06" rpy="0 1.57 1.57"/>
<axis xyz="0 0 1"/>
</joint>

  <!-- Base Link -->
  <gazebo reference="base_link">

  <material>Gazebo/Red</material>
  </gazebo>

  <!-- link_one-->
  <gazebo reference="wheel_1">

    <material>Gazebo/Green</material>
  </gazebo>
  
    <!--link_two-->
  <gazebo reference="wheel_2">

    <material>Gazebo/Green</material>
  </gazebo>
  
      <!--link_three-->
  <gazebo reference="wheel_3">

    <material>Gazebo/Green</material>
  </gazebo>
  
<!--link_four-->
<gazebo reference="wheel_4">
	<material>Gazebo/Green</material>
</gazebo>
  
  
  

<transmission name="tran1">
    <type>transmission_interface/SimpleTransmission</type>
    <joint name="base_to_wheel1">
      <hardwareInterface>hardware_interface/VelocityJointInterface</hardwareInterface>
    </joint>
    <actuator name="motor1">
      <mechanicalReduction>1</mechanicalReduction>
    </actuator>
</transmission>

<transmission name="tran2">
    <type>transmission_interface/SimpleTransmission</type>
    <joint name="base_to_wheel2">
      <hardwareInterface>hardware_interface/VelocityJointInterface</hardwareInterface>
    </joint>
    <actuator name="motor2">
      <mechanicalReduction>1</mechanicalReduction>
    </actuator>
</transmission>

<transmission name="tran3">
    <type>transmission_interface/SimpleTransmission</type>
    <joint name="base_to_wheel3">
      <hardwareInterface>hardware_interface/VelocityJointInterface</hardwareInterface>
    </joint>
    <actuator name="motor3">
      <mechanicalReduction>1</mechanicalReduction>
    </actuator>
</transmission>

<transmission name="tran4">
    <type>transmission_interface/SimpleTransmission</type>
    <joint name="base_to_wheel4">
      <hardwareInterface>hardware_interface/VelocityJointInterface</hardwareInterface>
    </joint>
    <actuator name="motor4">
      <mechanicalReduction>1</mechanicalReduction>
    </actuator>
</transmission>

<!-- rfilename="libgazebo_ros_diff_drive.so" for normal wheel --><!-- filename="libgazebo_ros_planar_move.so for mechanim wheel -->
<gazebo>
  <plugin name="differential_drive_controller" filename="libgazebo_ros_planar_move.so">
    <alwaysOn>true</alwaysOn>
    <updateRate>100</updateRate>
    <leftJoint>base_to_wheel1</leftJoint>
    <rightJoint>base_to_wheel2</rightJoint>
    <leftJoint>base_to_wheel3</leftJoint>
    <rightJoint>base_to_wheel4</rightJoint>
    <wheelSeparation>0.35</wheelSeparation>
    <wheelDiameter>0.05</wheelDiameter>
    <wheelTorque>2</wheelTorque>
    <commandTopic>cmd_vel</commandTopic>
    <odometryTopic>odom</odometryTopic>
    <odometryFrame>odom</odometryFrame>
    <robotNamespace>mobile</robotNamespace>
    <robotBaseFrame>base_footprint</robotBaseFrame>
    <publishWheelTF>true</publishWheelTF>
    <publishWheelJointState>true</publishWheelJointState>
    <wheelAcceleration>0</wheelAcceleration>
    <wheelTorque>2</wheelTorque>
    <rosDebugLevel>na</rosDebugLevel>
  </plugin>
</gazebo>

</robot>
